Workbook
Name ESXi.CPU.Usable.Capacity.Allocation: 'Capacity Provider'!$D$24
Name ESXi.CPU.Usable.Capacity.Reservation: 'Capacity Provider'!$D$44
Name ESXi.CPU.Usable.Capacity.Utilization: 'Capacity Provider'!$D$19
Name Hypervisor.Overhead.CPU: 'Capacity Provider'!$D$17
Name Hypervisor.Overhead.Memory: 'Capacity Provider'!$D$27
Name Silver.VM.RAM: 'Capacity Consumer'!$D$26
Name Silver.VM.vCPU: 'Capacity Consumer'!$D$23

Sheet Read Me
A2: Goal
B3: How many VMs can I fit while balancing cost and performance?
B4: Aim to maximise usage of capacity. Stop when any of the cells under Capacity Used hit 100%
A6: Capacity vs Performance
B7: 3 models included
C8: Utilization | D8: Capacity uses thread as the unit. It does not care about the speed (performance) of the CPU.
C9: Allocation | D9: This needs a default overcommit ratio
C10: Reservation
A12: Class of Service
B13: Gold is 2x the price of Silver, and 4x the price of Bronze
B14: To support the pricing strategy, it needs to have consistent Price/Performance Ratio
B15: The "performance" part is achieved by both overcommit ratio and reservation
C16: Gold Class has half the overcommit ratio. The VM enjoys 2x the reservation amount of silver
C17: You can add Share, although that increases operational complexity
A19: Summary
B20: How many VM will fit on a typical ESXi with 64 cores and 768 GB of RAM?
D21: Capacity Model | E21: ESXi Usable Capacity | G21: How many Silver VM will fit?
E22: CPU | F22: Memory | G22: CPU | H22: Memory
D23: Allocation | E23: =ESXi.CPU.Usable.Capacity.Allocation -> 208.8 | F23: ='Capacity Provider'!D53 -> 1017.6 | G23: =E23/Silver.VM.vCPU -> 26.1 | H23: =F23/Silver.VM.RAM -> 31.8
D24: Reservation | E24: =ESXi.CPU.Usable.Capacity.Reservation -> 152 | G24: =E24/'Capacity Provider'!D3/(Silver.VM.vCPU*'Capacity Consumer'!D24) -> 25.333333 | H24: =F23/(Silver.VM.RAM*'Capacity Consumer'!D27) -> 63.6
D25: Utilization | E25: =ESXi.CPU.Usable.Capacity.Utilization -> 104.4 | G25: =E25/(Silver.VM.vCPU*'Capacity Consumer'!D25) -> 26.1 | H25: =F23/(Silver.VM.RAM*'Capacity Consumer'!D28) -> 37.411765
B26: CPU is more complex as it has 3 different units, hence 3 different numbers.
B27: Memory can have more VM as it includes 50% of memory tiering
A29: The sheets
B30: ESXi portion | D30: This covers the total capacity. Since the Usable Capacity is a function of the Overcommit Ratio, this is covered here too
B31: VM portion | D31: This covers the consumption.
D32: It has 3 scenarios, one for each class of services
D33: Each scenario has mixed workload as that's most common deployment
A35: Which cells can you modify?
C36: Do not modify. They are formula
C37: Modify the green cells to suit your scenario

Sheet Capacity Provider
A1: Total Capacity
B2: Capacity begin with ESXi. Choose a CPU and Memory size that is balanced to avoid wastage
B3: CPU Speed | D3: 2.5 | E3: Replace with the actual speed of your hardware
B4: Core | D4: 64 | E4: cores
B5: Thread | D5: =D4*2 -> 128 | E5: threads
B6: All Core Turbo | D6: 1.25 | E6: of base frequency. Replace with the actual speed of the CPU
E7: This is the actual speed the VM gets when all cores are running
B8: RAM | D8: 768 | E8: GB RAM
B9: NVMe | D9: =D8/2 -> 384 | E9: GB RAM. I'm using 50%
A11: Usable Capacity
B12: We need to calculate the Usable Capacity as Capacity must be based on amount available to VM
B13: Cluster HA
C14: Cluster size | D14: 10 | E14: ESXi hosts. 9 + 1 HA
C15: Cluster HA | D15: =1/D14 -> 0.1 | E15: 1 of 10 hosts is for availability, hence 10% buffer
B16: CPU: Utilization Model
C17: Hypervisor Overhead | D17: 12 | E17: threads for ESXi + vSAN + NSX. NSX EDP adds 2-4 cores. vSAN File Services needs 2 vCPU as it's a VM
E18: If you run vSAN dedupe, compress, and heavy network services, increase to 14
C19: Usable Capacity | D19: =(D5-Hypervisor.Overhead.CPU)*(1-D15) -> 104.4 | E19: threads available for VM. This is the amount we can overcommit
B20: CPU: Allocation Model
C21: Overcommit Ratio is measured against Usable Capacity, not Total
C22: Default Overcommit Ratio | D22: 2 | E22: vCPU per thread. Do not do over core as HT can be disabled
E23: 2 vCPU is chosen per thread as most of the time VM run well below 50%
C24: Usable Capacity | D24: =ESXi.CPU.Usable.Capacity.Utilization*D22 -> 208.8 | E24: vCPU
B25: Memory
C26: Unlike CPU, memory has the same Usable Capacity number for all 3 models
C27: Hypervisor Overhead | D27: 64 | E27: See CPU for explanation. Adjust accordingly
C28: Usable Capacity | D28: =(D8-Hypervisor.Overhead.Memory)*(1-D15) -> 633.6 | E28: vRAM available for VM. Memory Tiering is not yet included because Gold has no overcommit
B30: ESXi CPU : RAM ratio | D30: =D28/ESXi.CPU.Usable.Capacity.Utilization -> 6.0689655 | E30: This means we can go memory heavy. If your workload is CPU heavy, buy less RAM
C31: Because it's higher than the 4:1 ratio of the VM configuration, we should lower the CPU Reservation to maximise consumption
A33: Throughput Consideration
B34: When a core is running, its actual speed varies over time.
B35: The speed impacts the throughput. A slow down is speed is not the same as VM facing CPU ready or co-stop
B36: CPU Cycles
C37: Total CPU Cycles | D37: =D3*D4*1.25*D6 -> 250 | E37: HT gives 1.25x CPU cycles, not 2.x
E38: This is what you get when all cores run. To be conservative, we're not using this number in the capacity
C39: Hypervisor Overhead | D39: =D3*Hypervisor.Overhead.CPU -> 30 | E39: threads for ESXi + vSAN + NSX
C40: Overhead in % | D40: =D39/D37 -> 0.12 | E40: This is higher as HT does not give 2x
C41: Usable CPU Cycles | D41: =D37-D39 -> 220 | E41: To be conservative, we're not using this number in the capacity
B42: Reservation
C43: System Reservation | D43: 8 | E43: Typically this is around 8 GHz
...

Sheet Capacity Consumer
A2: Summary of ESXi Usable Capacity
B3: Memory uses memory tiering for non Gold. To be conservative, we only apply for allocation, not reservation
C5: Gold | D5: Silver | E5: Bronze
B6: Allocation Model
B7: CPU Usable Capacity | C7: ='Capacity Provider'!D50 -> 104.4 | D7: ='Capacity Provider'!E50 -> 208.8 | E7: ='Capacity Provider'!F50 -> 313.2
B8: Memory Usable Capacity | C8: ='Capacity Provider'!D52 -> 633.6 | D8: ='Capacity Provider'!E52 -> 950.4 | E8: ='Capacity Provider'!F52 -> 1267.2
B9: Memory Usable with Tiering | C9: ='Capacity Provider'!D53 -> 1017.6
B10: Reservation Model
B11: Usable Capacity (not visible) | C11: ='Capacity Provider'!D41 -> 220
B12: CPU Reservable Capacity | C12: =MIN('Capacity Provider'!D41, 'Capacity Provider'!D44) -> 152
B13: Memory Reservable Capacity | C13: =C8 -> 633.6
B14: Memory Reservable with Tiering | C14: ='Capacity Provider'!D53 -> 1017.6
B15: Reservation is computed in MHz, hence we need to follow
A17: Average VM Size
B18: As this is just at the planning stage, it's better to use 1 size for each class.
B19: We keep the ratio between Gold, Silver and Bronze consistent.
B20: GB RAM per vCPU | C20: 4 | D20: GB
B22: Typical VM Size | C22: Gold | D22: Silver | E22: Bronze
B23: Configured CPU | C23: =D23*2 -> 16 | D23: =E23*2 -> 8 | E23: 4
B24: Reserved percentage | C24: 0.6 | D24: =C24/2 -> 0.3 | E24: =D24/2 -> 0.15
B25: Expected Utilization "Together" | C25: 0.5 | D25: =C25 -> 0.5 | E25: =D25 -> 0.5
B26: Configured Memory | C26: =C23*C20 -> 64 | D26: =D23*C20 -> 32 | E26: =E23*C20 -> 16
B27: Reserved percentage | C27: 1 | D27: 0.5 | E27: 0.25
B28: Expected Utilization "Together" | C28: 0.85 | D28: =C28 -> 0.85 | E28: =D28 -> 0.85
B29: The ratio among the class of services matches the overcommit ratio. This makes it appear fair, which ease acceptance
B30: Reservation is set high as that's customers expectation
B31: CPU is set lower than memory as there is relatively less capacity available in this specific ESXi hardware spec.
B32: Reservation impacts DRS and Resource Pools as it makes the "chunk" bigger. While it's necessary in a spreadsheet, avoid using in actual production.
A34: Existing Data
B35: CPU Speed | C35: ='Capacity Provider'!D3 -> 2.5 | D35: GHz
B36: Total Thread
B37: To keep MS Excel formula readable, we copy the data on this sheet from the ESXi sheet
A39: How many VM can we fit?
B40: Because the ESXi runs mixed classes, which Usable Capacity do we use?
B41: We use Bronze, but we multiply the weight of Gold by 4x and Silver by 2x
B42: This matches the Price/Performance so it's fair to tenants
B43: How many VMs can be placed depends on the class of service. The following tables show 3 common scenarios
B44: Aim for around 90% - 110%
B45: The "Overall Planned Consumption" rows have been color coded for ease of checking
B46: The reason why it's not exact (e.g. 99%) is you're at planning stage.
...

Sheet Cost Comparison
A1: Public Cloud Cost
B2: This is based on the average of AWS, Azure and Google GCP
B3: CPU Price | C3: 171 | D3: per vCPU per year
B4: RAM Price | C4: 43 | D4: per GB per year
B5: Public Cloud does not have Class of Service. Gold VM is treated the same way as Bronze VM. The entire philosophy of public cloud is Cattle, not Pet.
B6: The cost is likely higher as the above does not include egress network
A8: Private Cloud Cost
B9: Private Cloud total cost | C9: =165000 -> 165000 | D9: per ESXi
B10: The cost needs to include 1 HA host per cluster. This model uses 9+1 hosts per cluster
A12: Planning Scenario: Mostly Gold VMs
B13: Class of Service | C13: No of VM | D13: VM Size | F13: Public Cloud Cost
D14: vCPU | E14: RAM
B15: Gold Class VM | C15: ='Capacity Consumer'!C56 -> 6 | D15: ='Capacity Consumer'!C$23 -> 16 | E15: ='Capacity Consumer'!C$26 -> 64 | F15: =C15*(D15*C$3+E15*C$4) -> 32928
B16: Silver Class VM | C16: ='Capacity Consumer'!C57 -> 1 | D16: ='Capacity Consumer'!D$23 -> 8 | E16: ='Capacity Consumer'!D$26 -> 32 | F16: =C16*(D16*C$3+E16*C$4) -> 2744
B17: Bronze Class VM | C17: ='Capacity Consumer'!C58 -> 3 | D17: ='Capacity Consumer'!E$23 -> 4 | E17: ='Capacity Consumer'!E$26 -> 16 | F17: =C17*(D17*C$3+E17*C$4) -> 4116
B18: Total | C18: =SUM(C15:C17) -> 10 | F18: =SUM(F15:F17) -> 39788
D20: 5 Year Public Cloud spending | F20: =F18*5 -> 198940
D21: Savings with Private Cloud | F21: =ROUNDDOWN(F20-C$9,-3) -> 33000
A23: Planning Scenario: Mostly Silver VMs
B24: Class of Service | C24: No of VM | D24: VM Size | F24: Public Cloud Cost
D25: vCPU | E25: RAM
B26: Gold Class VM | C26: ='Capacity Consumer'!C66 -> 2 | D26: ='Capacity Consumer'!C$23 -> 16 | E26: ='Capacity Consumer'!C$26 -> 64 | F26: =C26*(D26*C$3+E26*C$4) -> 10976
B27: Silver Class VM | C27: ='Capacity Consumer'!C67 -> 13 | D27: ='Capacity Consumer'!D$23 -> 8 | E27: ='Capacity Consumer'!D$26 -> 32 | F27: =C27*(D27*C$3+E27*C$4) -> 35672
B28: Bronze Class VM | C28: ='Capacity Consumer'!C68 -> 8 | D28: ='Capacity Consumer'!E$23 -> 4 | E28: ='Capacity Consumer'!E$26 -> 16 | F28: =C28*(D28*C$3+E28*C$4) -> 10976
B29: Total | C29: =SUM(C26:C28) -> 23 | F29: =SUM(F26:F28) -> 57624
D31: 5 Year Public Cloud spending | F31: =F29*5 -> 288120
D32: Savings with Private Cloud | F32: =ROUNDDOWN(F31-C$9,-3) -> 123000
A34: Planning Scenario: Mostly Bronze VMs
B35: Class of Service | C35: No of VM | D35: VM Size | F35: Public Cloud Cost
D36: vCPU | E36: RAM
B37: Gold Class VM | C37: ='Capacity Consumer'!C76 -> 1 | D37: ='Capacity Consumer'!C$23 -> 16 | E37: ='Capacity Consumer'!C$26 -> 64 | F37: =C37*(D37*C$3+E37*C$4) -> 5488
B38: Silver Class VM | C38: ='Capacity Consumer'!C77 -> 6 | D38: ='Capacity Consumer'!D$23 -> 8 | E38: ='Capacity Consumer'!D$26 -> 32 | F38: =C38*(D38*C$3+E38*C$4) -> 16464
B39: Bronze Class VM | C39: ='Capacity Consumer'!C78 -> 27 | D39: ='Capacity Consumer'!E$23 -> 4 | E39: ='Capacity Consumer'!E$26 -> 16 | F39: =C39*(D39*C$3+E39*C$4) -> 37044
B40: Total | C40: =SUM(C37:C39) -> 34 | F40: =SUM(F37:F39) -> 58996
D42: 5 Year Public Cloud spending | F42: =F40*5 -> 294980
D43: Savings with Private Cloud | F43: =ROUNDDOWN(F42-C$9,-3) -> 129000
A45: Reference
B46: For details how we got this number, see https://docs.google.com/spreadsheets/d/1gRXwvZSIhz_C2bEQbrHmQsudqYq47LI0xYcBBwxSXO8/edit?usp=sharing
